<?xml version="1.0" encoding="UTF-8"?>
<!-- Generated by org.testng.reporters.JUnitXMLReporter -->
<testsuite ignored="0" hostname="christina" failures="1" tests="1" name="TC04_IssueChequeBook_Edge" time="5.593" errors="0" timestamp="2025-08-19T15:06:36 IST">
  <testcase classname="TestCases.TC04_IssueChequeBookToTheSavingsAccountWith10LeavesAfterTransactionStopTheChequeAndRevoke" name="runTest" time="1.465">
    <failure type="java.lang.AssertionError" message="Test failed due to exception: Row 2 not found in sheet: TC04">
      <![CDATA[java.lang.AssertionError: Test failed due to exception: Row 2 not found in sheet: TC04
at org.testng.Assert.fail(Assert.java:111)
at TestCases.TC04_IssueChequeBookToTheSavingsAccountWith10LeavesAfterTransactionStopTheChequeAndRevoke.runTest(TC04_IssueChequeBookToTheSavingsAccountWith10LeavesAfterTransactionStopTheChequeAndRevoke.java:93)
at java.base/jdk.internal.reflect.NativeMethodAccessorImpl.invoke0(Native Method)
at java.base/jdk.internal.reflect.NativeMethodAccessorImpl.invoke(NativeMethodAccessorImpl.java:77)
at java.base/jdk.internal.reflect.DelegatingMethodAccessorImpl.invoke(DelegatingMethodAccessorImpl.java:43)
at java.base/java.lang.reflect.Method.invoke(Method.java:568)
at org.testng.internal.invokers.MethodInvocationHelper.invokeMethod(MethodInvocationHelper.java:141)
at org.testng.internal.invokers.TestInvoker.invokeMethod(TestInvoker.java:687)
at org.testng.internal.invokers.TestInvoker.invokeTestMethod(TestInvoker.java:230)
at org.testng.internal.invokers.MethodRunner.runInSequence(MethodRunner.java:63)
at org.testng.internal.invokers.TestInvoker$MethodInvocationAgent.invoke(TestInvoker.java:995)
at org.testng.internal.invokers.TestInvoker.invokeTestMethods(TestInvoker.java:203)
at org.testng.internal.invokers.TestMethodWorker.invokeTestMethods(TestMethodWorker.java:154)
at org.testng.internal.invokers.TestMethodWorker.run(TestMethodWorker.java:134)
at java.base/java.util.ArrayList.forEach(ArrayList.java:1511)
at org.testng.TestRunner.privateRun(TestRunner.java:741)
at org.testng.TestRunner.run(TestRunner.java:616)
at org.testng.SuiteRunner.runTest(SuiteRunner.java:421)
at org.testng.SuiteRunner$SuiteWorker.run(SuiteRunner.java:463)
at org.testng.internal.thread.ThreadUtil.lambda$execute$0(ThreadUtil.java:64)
at java.base/java.util.concurrent.FutureTask.run(FutureTask.java:264)
at java.base/java.util.concurrent.ThreadPoolExecutor.runWorker(ThreadPoolExecutor.java:1136)
at java.base/java.util.concurrent.ThreadPoolExecutor$Worker.run(ThreadPoolExecutor.java:635)
at java.base/java.lang.Thread.run(Thread.java:842)
]]>
    </failure>
  </testcase> <!-- runTest -->
</testsuite> <!-- TC04_IssueChequeBook_Edge -->
